<?xml version="1.0"?>
<robot xmlns:xacro="http://www.ros.org/wiki/xacro"  name="robot">

    <xacro:include filename="inertial_macros.xacro"/>

    <xacro:property name="chasis_length" value="0.335"/>
    <xacro:property name="chasis_width" value="0.262"/>
    <xacro:property name="chasis_height" value="0.138"/>
    <xacro:property name="chasis_mass" value="1.0"/>
    <xacro:property name="wheel_radius" value="0.033"/>
    <xacro:property name="wheel_thickness" value="0.026"/>
    <xacro:property name="wheel_mass" value="0.05"/>
    <xacro:property name="wheel_offset_x" value="0.226"/>
    <xacro:property name="wheel_offset_y" value="0.0.1485"/>
    <xacro:property name="wheel_offset_z" value="0.01"/>
    <xacro:property name="caster_wheel_radius" value="0.01"/>
    <xacro:property name="caster_wheel_mass" value="0.0.01"/>
    <xacro:property name="caster_wheel_offset_x" value="0.075"/>
    <xacro:property name="caster_wheel_offset_z" value="${wheel_offset_z - wheel_radius + caster_wheel_radius}"/>

    <material name="white">
        <color rgba="1 1 1 1"/>
    </material>

    <material name="orange">
        <color rgba="1 0.3 0.1 1"/>
    </material>

    <material name="blue">
        <color rgba="0.2 0.2 1 1"/>
    </material>

    <material name="red">
        <color rgba="1 0 0 1"/>
    </material>

    <material name="black">
        <color rgba="0 0 0 1"/>
    </material>

    <material name="green">
        <color rgba="0 1 0 1"/>
    </material>

    <!-- BASE LINK  -->
    <link name="base_link">

    </link>

    <!-- BASE FOOTPRINT LINK -->
    <joint name="base_footprint_joint" type="fixed">
        <parent link="base_link"/>
        <child link="base_footprint"/>
        <origin xyz="0 0 0" rpy="0 0 0"/>
    </joint>

    <link name="base_footprint">

    </link>

    <!-- CHASSIS LINK -->

    <joint name="chassis_joint" type="fixed">
        <parent link="base_link"/>
        <child link="chassis"/>
        <origin xyz="-0.1 0 0"/>
    </joint>

    <link name="chassis">
        <visual>
        <origin xyz="0.15 0 0.03424"/>
            <geometry>
                <box size="0.235 0.173 0.101"/>
            </geometry>
            <material name="orange"/>
        </visual>
        <collision>
        <origin xyz="0.15 0 0.03424"/>
            <geometry>
                <box size="0.235 0.173 0.101"/>
            </geometry>
            <material name="orange"/>
        </collision>
        <xacro:inertial_box mass="0.5" x="0.235" y="0.173" z="0.101">
            <origin xyz="0.15 0 0.03424" rpy="0 0 0"/>
        </xacro:inertial_box>
    </link>
    <gazebo reference="chassis">
        <material>Gazebo/Orange</material>
    </gazebo>

    <!-- REAR WHEELS -->
    <!-- LEFT WHEEL LINK -->
    <joint name="left_rear_wheel_joint" type="continuous">
        <parent link="base_link"/>
        <child link="left_rear_wheel"/>
        <origin xyz="-0.03075 0.1015 0" rpy="-${pi/2} 0 0"/>
        <axis xyz = "0 0 1"/>
    </joint>

    <link name="left_rear_wheel">
        <visual>
            <geometry>
                <cylinder radius="0.03725" length="0.02"/>
            </geometry>
            <material name="black"/>
        </visual>
        <collision>
            <geometry>
                 <sphere radius="0.03725" /> <!--length="0.04" for cylinder -->
            </geometry>
            <material name="black"/>
        </collision>
        <xacro:inertial_cylinder mass="0.1" length="0.02" radius="0.03725">
            <origin xyz="0 0 0" rpy="0 0 0"/>
        </xacro:inertial_cylinder>
    </link>
    <gazebo reference="left_rear_wheel">
        <material>Gazebo/Black</material>
    </gazebo>

    <!-- RIGHT WHEEL LINK -->
    <joint name="right_rear_wheel_joint" type="continuous">
        <parent link="base_link"/>
        <child link="right_rear_wheel"/>
        <origin xyz="-0.03075 -0.1015 0" rpy="${pi/2} 0 0"/>
        <axis xyz = "0 0 -1"/>
    </joint>

    <link name="right_rear_wheel">
        <visual>
            <geometry>
                <cylinder radius="0.03725" length="0.02"/>
            </geometry>
            <material name="black"/>
        </visual>
        <collision>
            <geometry>
                <sphere radius="0.03725"/> <!--length="0.04" for cylinder -->
            </geometry>
            <material name="black"/>
        </collision>
        <xacro:inertial_cylinder mass="0.1" length="0.02" radius="0.03725">
            <origin xyz="0 0 0" rpy="0 0 0"/>
        </xacro:inertial_cylinder>
    </link>
    <gazebo reference="right_rear_wheel">
        <material>Gazebo/Black</material>
    </gazebo>

    <!-- FRONT WHEEEELS  -->  
    <!-- LEFT WHEEL  -->  
    <joint name="left_front_wheel_joint" type="continuous">
        <parent link="base_link"/>
        <child link="left_front_wheel"/>
        <origin xyz="0.12325 0.1015 0" rpy="-${pi/2} 0 0"/>
        <axis xyz = "0 0 1"/>
    </joint>

    <link name="left_front_wheel">
        <visual>
            <geometry>
                <cylinder radius="0.03725" length="0.02"/>
            </geometry>
            <material name="black"/>
        </visual>
        <collision>
            <geometry>
                 <sphere radius="0.03725" /> <!--length="0.04" for cylinder -->
            </geometry>
            <material name="black"/>
        </collision>
        <xacro:inertial_cylinder mass="0.1" length="0.02" radius="0.03725">
            <origin xyz="0 0 0" rpy="0 0 0"/>
        </xacro:inertial_cylinder>
    </link>
    <gazebo reference="left_front_wheel">
        <material>Gazebo/Black</material>
        <mu1 value="0.001"/>
        <mu2 value="0.001"/>
    </gazebo>

    <!-- RIGHT WHEEL LINK -->
    <joint name="right_front_wheel_joint" type="continuous">
        <parent link="base_link"/>
        <child link="right_front_wheel"/>
        <origin xyz="0.12325 -0.1015 0" rpy="${pi/2} 0 0"/>
        <axis xyz = "0 0 -1"/>
    </joint>

    <link name="right_front_wheel">
        <visual>
            <geometry>
                <cylinder radius="0.03725" length="0.02"/>
            </geometry>
            <material name="black"/>
        </visual>
        <collision>
            <geometry>
                <sphere radius="0.03725"/> <!--length="0.04" for cylinder -->
            </geometry>
            <material name="black"/>
        </collision>
        <xacro:inertial_cylinder mass="0.1" length="0.02" radius="0.03725">
            <origin xyz="0 0 0" rpy="0 0 0"/>
        </xacro:inertial_cylinder>
    </link>
    <gazebo reference="right_front_wheel">
        <material>Gazebo/Black</material>
        <mu1 value="0.001"/>
        <mu2 value="0.001"/>
    </gazebo>

</robot>